
test_add_group.py:22: 
_ _ _ _ _ _ _ _ _ _ _ _ _ _ _ _ _ _ _ _ _ _ _ _ _ _ _ _ _ _ _ _ _ _ _ _ _ _ _ _
application.py:43: in login
    self.open_home_page()
application.py:53: in open_home_page
    wd.get("http://localhost/addressbook/group.php")
venv\lib\site-packages\selenium\webdriver\remote\webdriver.py:333: in get
    self.execute(Command.GET, {'url': url})
venv\lib\site-packages\selenium\webdriver\remote\webdriver.py:319: in execute
    response = self.command_executor.execute(driver_command, params)
venv\lib\site-packages\selenium\webdriver\remote\remote_connection.py:374: in execute
    return self._request(command_info[0], url, body=data)
venv\lib\site-packages\selenium\webdriver\remote\remote_connection.py:397: in _request
    resp = self._conn.request(method, url, body=body, headers=headers)
venv\lib\site-packages\urllib3\request.py:72: in request
    **urlopen_kw)
venv\lib\site-packages\urllib3\request.py:150: in request_encode_body
    return self.urlopen(method, url, **extra_kw)
venv\lib\site-packages\urllib3\poolmanager.py:323: in urlopen
    response = conn.urlopen(method, u.request_uri, **kw)
venv\lib\site-packages\urllib3\connectionpool.py:667: in urlopen
    **response_kw)
venv\lib\site-packages\urllib3\connectionpool.py:667: in urlopen
    **response_kw)
venv\lib\site-packages\urllib3\connectionpool.py:667: in urlopen
    **response_kw)
venv\lib\site-packages\urllib3\connectionpool.py:638: in urlopen
    _stacktrace=sys.exc_info()[2])
_ _ _ _ _ _ _ _ _ _ _ _ _ _ _ _ _ _ _ _ _ _ _ _ _ _ _ _ _ _ _ _ _ _ _ _ _ _ _ _

self = Retry(total=0, connect=None, read=None, redirect=None, status=None)
method = 'POST', url = '/session/475a0c79-995c-45ff-b242-fab6e4b19501/url'
response = None
error = NewConnectionError('<urllib3.connection.HTTPConnection object at 0x000001AE961BCA20>: Failed to establish a new connection: [WinError 10061] No connection could be made because the target machine actively refused it',)
_pool = <urllib3.connectionpool.HTTPConnectionPool object at 0x000001AE95A52978>
_stacktrace = <traceback object at 0x000001AE95E7CC48>

    def increment(self, method=None, url=None, response=None, error=None,
                  _pool=None, _stacktrace=None):
        """ Return a new Retry object with incremented retry counters.
    
        :param response: A response object, or None, if the server did not
            return a response.
        :type response: :class:`~urllib3.response.HTTPResponse`
        :param Exception error: An error encountered during the request, or
            None if the response was received successfully.
    
        :return: A new ``Retry`` object.
        """
        if self.total is False and error:
            # Disabled, indicate to re-raise the error.
            raise six.reraise(type(error), error, _stacktrace)
    
        total = self.total
        if total is not None:
            total -= 1
    
        connect = self.connect
        read = self.read
        redirect = self.redirect
        status_count = self.status
        cause = 'unknown'
        status = None
        redirect_location = None
    
        if error and self._is_connection_error(error):
            # Connect retry?
            if connect is False:
                raise six.reraise(type(error), error, _stacktrace)
            elif connect is not None:
                connect -= 1
    
        elif error and self._is_read_error(error):
            # Read retry?
            if read is False or not self._is_method_retryable(method):
                raise six.reraise(type(error), error, _stacktrace)
            elif read is not None:
                read -= 1
    
        elif response and response.get_redirect_location():
            # Redirect retry?
            if redirect is not None:
                redirect -= 1
            cause = 'too many redirects'
            redirect_location = response.get_redirect_location()
            status = response.status
    
        else:
            # Incrementing because of a server error like a 500 in
            # status_forcelist and a the given method is in the whitelist
            cause = ResponseError.GENERIC_ERROR
            if response and response.status:
                if status_count is not None:
                    status_count -= 1
                cause = ResponseError.SPECIFIC_ERROR.format(
                    status_code=response.status)
                status = response.status
    
        history = self.history + (RequestHistory(method, url, error, status, redirect_location),)
    
        new_retry = self.new(
            total=total,
            connect=connect, read=read, redirect=redirect, status=status_count,
            history=history)
    
        if new_retry.is_exhausted():
>           raise MaxRetryError(_pool, url, error or ResponseError(cause))
E           urllib3.exceptions.MaxRetryError: HTTPConnectionPool(host='127.0.0.1', port=44252): Max retries exceeded with url: /session/475a0c79-995c-45ff-b242-fab6e4b19501/url (Caused by NewConnectionError('<urllib3.connection.HTTPConnection object at 0x000001AE961BCA20>: Failed to establish a new connection: [WinError 10061] No connection could be made because the target machine actively refused it',))

venv\lib\site-packages\urllib3\util\retry.py:398: MaxRetryError
------------------------------ Captured log call ------------------------------
connectionpool.py          662 WARNING  Retrying (Retry(total=2, connect=None, read=None, redirect=None, status=None)) after connection broken by 'NewConnectionError('<urllib3.connection.HTTPConnection object at 0x000001AE95A52F60>: Failed to establish a new connection: [WinError 10061] No connection could be made because the target machine actively refused it',)': /session/475a0c79-995c-45ff-b242-fab6e4b19501/url
connectionpool.py          662 WARNING  Retrying (Retry(total=1, connect=None, read=None, redirect=None, status=None)) after connection broken by 'NewConnectionError('<urllib3.connection.HTTPConnection object at 0x000001AE961BC748>: Failed to establish a new connection: [WinError 10061] No connection could be made because the target machine actively refused it',)': /session/475a0c79-995c-45ff-b242-fab6e4b19501/url
connectionpool.py          662 WARNING  Retrying (Retry(total=0, connect=None, read=None, redirect=None, status=None)) after connection broken by 'NewConnectionError('<urllib3.connection.HTTPConnection object at 0x000001AE961BC668>: Failed to establish a new connection: [WinError 10061] No connection could be made because the target machine actively refused it',)': /session/475a0c79-995c-45ff-b242-fab6e4b19501/url
===================== 2 failed, 2 error in 22.34 seconds ======================
Process finished with exit code 0
